tests/64_threads/sample_52.in
64
o
43 S 101 1 167 573
52 S 102 5 151 743
45 S 103 4 109 459
53 S 104 7 199 830
58 S 105 4 176 109
39 S 106 1 155 102
9 S 107 4 142 71
10 B 108 2 179 858
52 C 102
4 B 110 8 159 694
58 B 115 7 187 390
19 B 116 7 109 261
29 B 117 8 187 149
43 S 118 9 159 621
51 S 120 5 171 411
51 C 120
50 S 122 4 177 277
26 S 125 9 196 888
18 S 128 3 108 918
9 S 129 5 189 879
27 B 130 8 108 461
46 S 131 1 179 784
36 S 134 4 194 24
39 C 106
33 S 137 4 185 171
15 B 138 9 199 15
43 C 118
50 S 142 6 142 441
59 S 143 7 169 668
4 C 110
36 S 145 0 137 521
22 S 146 2 184 818
20 B 147 9 130 30
54 S 149 6 150 911
54 B 150 7 154 919
7 S 151 5 164 845
59 S 152 2 167 13
61 S 153 1 116 320
29 B 154 3 165 560
18 C 128
22 S 156 6 127 300
47 S 157 5 100 813
13 B 158 2 101 274
61 C 153
17 S 162 5 143 440
36 C 134
62 S 164 8 120 275
50 C 122
35 S 166 9 100 290
53 C 104
36 B 168 4 101 939
50 C 122
4 B 171 5 170 502
13 S 172 7 126 813
6 B 173 0 161 323
7 C 151
27 S 176 0 129 958
60 S 179 4 146 104
23 S 180 6 198 245
47 C 157
0 S 183 2 123 349
51 C 120
35 B 185 4 139 97
44 B 186 1 195 298
43 S 187 1 131 940
13 C 158
4 S 190 9 168 953
7 C 151
62 C 164
58 S 194 4 106 285
33 C 137
54 B 196 3 123 800
55 S 197 4 179 188
37 S 199 0 130 577
5 B 200 4 173 675
22 C 146
10 S 203 1 127 882
61 B 204 4 130 68
24 B 205 6 198 24
61 C 204
19 C 116
27 C 176
24 S 210 4 131 622
19 B 211 0 172 501
22 C 156
56 S 214 0 180 650
43 C 118
40 S 216 4 182 137
51 S 217 0 156 431
54 S 218 3 157 766
51 S 219 8 166 225
61 C 204
10 C 108
33 C 137
62 C 164
5 C 200
17 S 226 3 143 721
43 B 227 8 101 682
29 C 154
27 S 229 0 147 810
56 B 230 0 168 808
9 C 129
23 S 232 9 114 95
20 C 147
14 B 234 4 104 724
37 S 236 6 160 511
51 B 237 2 104 965
0 C 183
62 C 164
18 C 128
57 B 242 9 160 10
6 C 173
63 B 246 5 198 660
35 S 247 9 170 71
31 B 248 3 172 743
22 S 249 4 115 478
42 B 250 6 153 729
53 B 251 6 191 287
33 S 253 1 136 150
23 C 180
36 C 134
5 B 256 4 107 125
31 B 257 2 104 287
57 C 242
54 B 260 7 189 653
37 B 261 8 148 891
62 B 262 2 118 89
15 C 138
45 C 103
16 S 265 8 175 567
7 C 151
51 B 268 3 158 663
45 B 269 2 112 899
12 B 270 4 190 382
45 S 271 8 132 747
57 B 272 6 165 533
15 B 273 9 106 528
54 C 196
26 C 125
9 B 276 0 100 174
45 S 277 6 133 673
61 B 278 5 193 578
50 B 279 7 196 636
12 C 270
39 B 282 9 143 285
0 B 283 4 107 993
7 C 151
39 C 282
20 C 147
28 S 287 8 136 866
4 C 171
19 C 211
61 C 153
32 S 291 2 150 210
7 C 151
62 S 293 2 177 456
36 C 145
39 B 295 7 158 800
20 B 296 4 134 892
29 B 297 6 125 375
18 C 128
8 S 299 9 167 204
9 C 129
28 S 301 9 127 783
51 C 237
0 S 303 6 184 345
29 S 304 3 147 995
15 S 305 2 125 723
23 B 306 6 115 450
16 S 307 9 148 859
62 S 308 1 191 180
54 B 309 9 106 765
33 C 253
52 S 311 6 148 740
32 C 291
58 B 313 4 200 30
44 C 186
28 S 315 1 118 77
14 C 234
20 S 317 7 115 923
53 S 319 1 126 569
4 S 320 5 138 373
8 C 299
5 B 322 3 177 209
7 S 323 9 150 543
42 B 324 4 131 27
31 S 325 0 127 147
55 S 326 8 163 205
5 B 327 1 124 791
39 S 328 0 157 475
28 B 329 4 139 873
60 S 330 2 105 829
20 S 331 9 164 863
31 C 248
12 S 333 2 173 132
14 C 234
37 B 335 0 142 892
37 B 337 9 155 899
30 B 338 1 197 403
42 S 340 7 130 257
10 S 341 3 110 798
37 S 342 2 129 489
0 B 343 2 190 177
54 S 344 3 156 877
59 B 345 3 152 188
62 S 346 4 147 716
35 B 348 1 152 93
3 B 349 9 150 419
15 S 350 0 170 854
53 C 251
21 S 352 5 165 818
29 S 353 2 103 370
23 C 306
45 C 277
36 S 358 5 168 198
16 C 307
6 C 173
21 S 361 1 185 769
53 C 104
46 S 363 9 153 189
12 C 270
42 B 366 6 165 426
1 B 367 2 196 893
36 S 368 3 123 828
7 C 151
4 B 370 6 125 224
28 S 371 9 135 237
63 S 372 8 199 64
40 B 373 9 182 936
53 B 374 9 114 198
21 B 375 6 162 879
10 B 376 4 190 805
9 C 107
28 S 378 1 150 21
18 B 379 0 106 63
51 S 380 1 190 912
18 B 381 8 109 828
16 B 382 6 105 434
49 B 383 3 103 978
28 S 384 8 184 723
38 S 385 2 141 483
42 C 324
17 B 387 5 176 69
39 C 328
38 B 389 3 147 581
30 C 338
6 B 391 3 109 190
16 B 392 8 118 178
21 B 393 4 144 307
39 S 394 3 192 194
57 C 242
1 S 396 7 126 530
42 S 397 9 192 615
52 B 398 8 200 834
10 S 399 2 174 338
22 S 400 6 119 244
52 B 401 9 181 669
20 C 331
16 B 403 5 177 513
4 S 404 0 143 555
7 C 323
5 B 406 2 173 260
57 B 407 9 167 883
18 C 128
45 C 103
0 C 183
40 S 411 2 109 938
51 S 412 2 190 951
37 B 413 7 119 718
4 C 320
29 S 415 0 101 855
6 S 416 1 147 253
12 C 270
35 B 419 3 171 109
43 S 420 2 155 510
53 S 421 4 100 658
51 B 422 0 143 211
34 S 423 2 138 86
59 C 152
26 B 425 4 123 502
49 B 426 4 186 544
56 B 427 3 170 59
54 C 196
33 C 137
13 B 430 5 103 787
17 B 431 2 183 781
8 C 299
40 S 433 0 176 168
38 S 434 3 187 819
13 B 435 1 100 903
10 B 436 8 114 307
15 S 437 0 165 908
20 B 438 5 150 396
5 C 256
33 S 440 4 111 809
55 B 441 7 129 387
20 B 442 8 101 305
58 C 194
63 B 444 4 169 77
42 B 445 2 174 522
54 B 446 1 130 10
31 C 325
22 C 156
1 S 449 2 120 141
26 S 450 1 199 893
33 S 451 6 189 608
29 S 452 4 170 213
33 B 453 6 192 51
0 C 343
51 B 455 5 134 438
56 C 214
49 B 457 7 122 295
25 B 458 1 155 755
54 B 459 0 190 357
46 S 460 1 151 173
16 S 461 5 104 36
57 S 462 7 196 666
54 C 459
28 C 378
19 C 211
18 B 466 0 173 122
45 S 467 9 190 392
14 C 234
27 S 469 2 178 997
10 C 341
36 S 471 6 198 185
15 S 472 8 188 25
42 S 473 5 152 735
31 B 474 9 157 260
51 C 237
12 C 270
12 S 477 0 158 657
63 C 246
61 B 479 2 102 569
3 C 349
1 B 481 0 106 311
52 C 398
38 S 483 4 127 88
53 B 484 0 191 469
16 S 485 0 116 421
5 B 486 3 122 220
26 B 487 7 184 494
25 S 488 7 190 809
37 B 489 7 175 921
13 B 490 7 102 503
35 S 491 7 147 120
58 S 492 2 187 683
30 B 493 8 184 786
54 C 344
38 C 385
50 S 496 5 125 298
1 C 396
23 S 498 9 162 373
21 C 375
40 B 500 1 151 195
63 S 501 7 110 200
22 C 146
1 B 503 1 152 774
9 B 504 1 132 784
22 S 505 4 165 108
39 C 328
11 B 507 2 139 339
43 C 187
18 C 466
53 C 374
37 S 511 8 116 646
26 S 512 6 164 442
55 C 441
12 C 477
40 B 515 7 193 408
22 S 516 0 131 194
9 S 517 3 142 281
14 S 518 2 165 309
52 C 102
3 C 349
6 S 521 7 125 329
29 S 522 5 163 375
57 B 523 6 100 935
27 C 130
34 B 525 0 198 91
3 S 526 0 142 77
31 S 527 5 107 591
28 S 528 6 152 108
55 C 326
58 B 530 1 192 351
11 B 531 7 199 813
42 C 250
53 S 533 4 142 581
6 B 534 3 128 836
5 B 535 1 174 820
40 C 411
16 S 537 6 173 199
44 S 538 9 193 283
60 S 539 4 177 931
59 C 143
8 B 541 0 170 912
10 C 108
49 B 543 4 118 732
54 B 544 5 200 778
14 C 234
19 B 546 3 186 654
36 C 368
24 B 548 6 129 938
33 C 451
9 C 107
19 S 551 2 173 879
58 B 552 1 132 305
34 S 553 2 131 729
15 C 273
20 C 147
3 B 556 0 196 553
60 S 557 6 100 550
20 B 558 4 113 939
59 S 559 8 157 516
56 S 560 2 152 320
17 C 226
0 B 562 0 138 663
16 S 563 7 168 104
32 S 564 4 194 234
26 C 450
48 S 566 1 110 951
41 S 567 8 187 929
10 B 568 9 100 97
36 B 569 2 138 865
38 B 570 8 142 872
53 S 571 1 196 442
35 S 572 8 154 571
52 B 573 4 170 943
26 B 574 2 164 211
11 C 531
21 S 576 5 176 726
11 C 531
37 B 578 8 141 545
15 B 579 2 139 413
46 C 460
42 S 581 9 198 305
47 S 582 0 131 254
45 C 271
45 S 584 0 171 549
39 C 394
16 B 586 4 178 710
51 S 587 1 178 426
62 C 262
24 B 589 9 180 175
42 S 590 4 200 546
32 B 591 9 185 231
11 C 507
62 S 593 7 107 171
58 S 594 9 125 353
20 C 438
33 C 253
34 S 597 3 176 852
30 S 598 7 133 580
5 S 599 4 162 978
36 B 600 4 133 704
5 S 601 2 142 451
3 C 526
7 C 151
56 B 604 6 200 390
59 S 605 1 193 988
61 S 606 8 144 555
3 C 556
48 C 566
32 C 291
6 S 610 9 103 64
27 C 130
3 S 612 8 194 123
21 S 613 6 150 275
51 S 614 0 110 915
24 B 615 8 157 820
9 B 616 6 186 427
6 B 617 7 187 88
30 C 338
12 C 477
62 S 620 6 192 737
35 C 166
53 B 622 2 180 586
46 B 623 6 194 17
4 B 624 2 148 341
34 B 625 2 135 528
16 B 626 5 137 413
10 C 341
16 S 628 1 174 638
31 B 629 7 115 203
39 C 282
20 C 147
33 B 632 8 153 338
41 B 633 2 147 283
10 C 203
7 C 151
23 C 498
53 B 637 5 146 361
23 B 638 3 107 557
11 C 531
3 C 526
16 S 641 0 188 556
6 B 642 4 114 465
7 S 643 9 176 419
37 B 644 6 161 752
7 B 645 8 177 841
14 S 646 8 102 672
13 S 647 1 112 872
24 B 648 6 172 893
43 S 649 0 170 357
22 B 650 9 118 625
20 S 651 5 163 87
41 S 652 0 199 315
51 C 380
22 B 654 3 154 717
51 S 655 9 120 741
