tests/64_threads/sample_53.in
64
o
58 S 101 3 177 490
54 B 102 4 164 421
30 S 103 6 165 409
21 B 104 5 158 969
22 S 106 0 190 383
11 B 107 2 182 47
62 B 108 2 147 121
45 S 111 3 156 512
14 S 112 9 140 723
38 S 113 8 114 808
38 C 113
30 B 116 0 134 160
38 S 117 9 196 443
44 B 118 4 184 846
27 S 119 4 120 988
48 S 120 9 153 840
28 S 121 8 185 954
19 B 122 7 151 752
21 S 123 0 182 238
5 B 125 8 149 54
16 S 126 4 197 174
57 S 127 2 106 583
53 S 128 0 144 721
60 B 129 9 117 899
62 S 130 6 112 468
62 C 108
42 S 132 5 125 417
33 S 133 9 161 354
39 S 134 2 137 303
35 B 135 0 190 239
16 B 136 4 111 548
12 S 138 8 120 131
5 C 125
18 S 140 7 117 139
0 B 141 0 101 145
52 B 142 6 121 921
24 S 143 1 126 38
53 B 144 2 167 879
49 S 145 3 199 844
9 B 146 8 104 851
34 B 147 7 186 428
5 C 125
37 B 150 9 174 281
34 S 152 2 116 986
48 B 153 2 184 634
34 B 154 0 149 127
19 B 155 1 198 922
35 C 135
14 C 112
28 B 160 6 146 365
8 B 161 5 163 867
62 B 162 1 198 597
11 C 107
33 B 164 8 158 107
35 B 165 4 119 469
27 S 166 3 151 537
54 S 167 1 136 914
63 S 168 4 134 205
60 S 169 7 131 94
34 C 154
17 S 171 9 172 657
44 C 118
33 S 173 8 172 882
16 S 174 3 199 376
36 B 175 9 150 962
29 S 176 2 104 808
63 B 177 7 102 714
5 S 178 9 139 211
34 B 180 9 139 542
0 S 181 4 135 133
22 C 106
52 C 142
20 S 185 7 142 503
20 B 186 9 102 971
48 C 153
21 S 188 8 146 811
9 S 190 5 196 421
16 S 191 8 148 705
1 S 192 0 185 331
36 S 193 8 110 844
49 S 194 3 196 85
41 S 195 6 171 252
12 S 196 4 131 682
1 C 192
58 B 198 7 117 935
25 S 199 8 145 744
3 B 201 7 200 734
60 B 202 1 172 36
5 B 203 9 175 350
7 S 204 1 159 727
20 B 205 0 119 980
38 C 113
47 B 207 1 134 745
25 S 208 6 166 29
39 C 134
23 S 210 0 135 495
37 B 211 7 187 114
26 B 212 4 186 26
44 B 214 2 108 929
18 C 140
3 B 217 9 134 483
49 B 218 0 128 753
53 C 128
49 S 220 2 177 952
7 C 204
55 B 223 7 110 612
51 S 224 2 172 50
58 S 226 1 154 330
3 C 201
38 S 228 6 192 130
36 C 175
24 B 230 4 140 930
29 C 176
34 B 232 5 196 372
33 C 164
11 S 234 0 133 243
56 S 235 3 105 458
7 C 204
49 C 220
51 B 239 0 159 830
6 B 240 9 195 481
48 B 241 5 121 682
53 C 128
20 C 205
58 S 245 5 190 660
25 S 246 4 102 126
52 C 142
62 S 249 6 100 796
43 S 250 0 166 373
12 C 138
11 S 252 2 129 756
30 B 253 0 176 448
25 S 255 1 129 665
17 S 256 5 184 150
39 C 134
20 S 258 6 156 711
61 B 259 2 183 911
30 B 260 6 178 78
15 S 261 8 125 175
51 B 262 6 143 877
16 S 263 7 184 351
60 S 264 5 166 230
62 S 265 6 122 614
22 B 266 7 100 500
49 C 218
56 S 268 6 196 591
8 C 161
14 S 270 1 180 203
19 B 271 3 183 567
60 S 272 4 121 278
51 B 274 9 168 18
40 S 275 6 105 217
43 S 276 4 103 310
4 S 277 5 116 207
17 C 171
60 S 279 8 163 710
48 B 280 8 140 488
40 B 281 0 161 255
1 C 192
30 S 283 1 163 523
30 S 284 6 118 420
25 C 199
1 C 192
2 S 287 6 168 776
20 B 288 3 105 93
11 S 289 3 165 942
8 C 161
39 C 134
57 C 127
55 S 293 9 138 229
26 C 212
61 B 295 9 172 791
24 S 296 4 178 838
23 S 297 5 111 533
2 S 298 5 154 304
16 S 299 5 184 195
5 C 178
36 C 175
63 B 302 6 177 796
20 S 303 2 130 129
21 C 123
36 B 305 0 102 166
30 C 116
38 B 307 4 191 24
20 B 308 8 183 21
4 S 309 7 120 673
5 S 310 3 197 90
2 B 311 8 142 165
18 S 312 3 108 119
14 B 313 8 116 600
52 S 314 0 166 91
52 B 315 3 109 650
58 C 226
3 B 317 3 176 93
40 S 318 9 136 615
63 S 319 5 118 805
26 S 320 5 198 889
9 C 190
37 C 150
48 C 241
48 C 120
2 B 325 7 190 956
9 B 326 4 176 661
3 C 201
1 B 328 6 126 856
2 S 329 3 150 530
35 B 330 9 141 353
39 C 134
54 S 332 7 131 153
1 C 192
62 B 334 0 149 986
58 S 335 8 148 836
26 S 336 1 117 495
18 S 337 6 192 467
35 S 338 0 197 926
41 S 339 1 124 328
0 S 340 7 131 605
45 C 111
43 C 250
35 B 343 5 138 953
57 S 344 4 136 782
41 C 195
20 C 258
17 C 171
23 B 348 1 104 599
26 C 336
25 C 246
32 B 351 6 150 486
3 S 353 9 100 571
6 C 240
20 S 355 2 122 55
5 S 356 0 149 791
62 S 357 4 123 852
58 B 358 3 178 971
62 B 359 5 107 930
14 B 360 1 178 304
56 S 361 1 121 817
55 S 362 5 199 100
14 C 313
41 S 364 5 133 786
37 S 365 8 103 932
49 B 366 5 106 726
32 B 367 4 130 481
21 S 368 3 138 702
10 S 369 5 157 225
3 C 353
30 C 284
13 S 372 5 119 95
11 B 373 5 189 859
2 S 374 2 142 695
30 C 260
32 C 351
1 C 328
22 B 379 5 160 837
28 C 121
38 B 381 4 142 765
27 S 382 8 106 140
21 C 123
53 C 128
27 C 166
62 C 357
31 B 387 3 156 730
27 C 119
4 C 309
26 B 390 3 136 314
11 B 391 2 192 642
24 S 392 6 165 788
16 B 393 7 122 296
29 S 394 3 130 838
28 B 395 1 167 832
49 S 396 9 149 968
5 B 397 7 129 142
13 S 398 7 149 261
27 B 399 6 195 67
32 B 400 3 144 263
47 B 401 7 103 598
41 S 402 7 148 36
12 C 138
48 B 404 7 172 426
36 S 405 0 163 449
15 B 407 0 199 983
13 S 409 3 152 144
38 B 410 0 184 807
54 B 411 0 196 863
13 B 412 0 167 820
38 S 413 3 200 900
34 S 414 0 102 249
5 C 178
16 C 126
55 C 223
51 B 418 8 107 154
48 C 153
24 B 420 2 167 188
35 B 421 8 146 429
60 S 422 5 107 309
63 C 302
49 S 424 1 106 479
3 B 425 5 114 692
55 C 223
41 B 427 3 160 302
4 B 428 0 197 316
41 B 429 0 153 899
14 S 430 3 111 131
61 S 431 9 114 561
13 B 432 5 120 385
19 S 433 9 142 493
50 B 434 1 166 667
10 B 435 5 162 643
40 C 275
44 B 437 0 171 304
57 C 127
6 C 240
36 C 305
11 S 441 2 146 346
20 S 442 7 135 553
14 C 430
57 S 444 4 114 116
19 S 445 5 117 307
18 C 337
5 S 447 7 179 604
12 B 448 6 115 104
6 C 240
24 C 420
5 S 451 1 190 825
50 B 452 7 154 262
44 S 453 1 103 837
12 C 196
6 S 455 7 170 425
52 C 142
50 B 457 4 200 656
34 C 147
29 C 394
11 B 460 4 135 849
45 S 461 6 184 334
9 B 462 1 106 934
56 B 463 8 158 868
49 S 464 7 171 284
59 B 465 7 109 994
60 B 466 9 143 368
13 C 398
55 C 293
54 S 469 9 126 280
26 C 390
35 B 471 0 140 400
40 S 472 1 157 489
3 B 473 7 128 827
15 C 261
62 S 475 8 153 977
4 B 476 8 101 772
29 S 477 9 170 335
42 S 478 8 169 947
37 B 479 2 143 714
10 S 480 9 127 459
8 C 161
52 S 482 8 102 633
26 B 483 6 172 829
1 C 328
58 S 485 7 128 863
15 S 486 5 174 20
20 C 258
31 C 387
2 C 311
4 C 476
27 B 491 8 172 915
38 B 492 2 142 576
20 B 493 3 182 559
9 B 494 4 138 254
1 S 495 2 124 79
3 C 317
46 B 497 7 168 635
6 S 498 7 182 57
25 C 246
34 B 500 9 104 683
21 B 501 5 160 595
0 C 340
47 S 503 7 116 46
37 C 150
27 C 491
5 S 506 9 100 67
41 S 507 0 193 959
25 C 199
8 S 509 3 167 424
54 B 510 6 137 295
25 B 511 2 165 378
61 C 259
57 S 513 8 196 769
59 B 514 6 119 721
37 B 515 2 143 521
29 B 516 5 110 156
1 S 517 2 163 709
15 B 518 9 132 900
36 S 519 4 153 692
35 B 520 0 101 871
49 S 521 8 167 492
5 S 522 7 155 516
61 C 259
52 B 524 3 137 20
46 B 525 4 114 211
14 B 526 0 164 971
2 C 329
27 B 528 5 181 254
20 S 529 7 191 524
63 S 530 2 113 465
8 C 161
45 B 532 1 158 86
18 C 312
26 S 534 0 123 408
14 B 535 8 127 823
5 C 125
54 B 537 3 160 877
41 C 429
6 S 539 1 115 862
11 S 540 1 154 787
45 B 541 5 183 912
49 C 396
57 B 543 2 191 804
23 C 297
24 S 545 1 143 664
52 C 524
60 S 547 5 173 791
27 B 548 3 200 579
34 B 549 6 154 408
59 B 550 4 108 888
4 S 551 6 167 912
20 B 552 5 132 862
17 C 171
57 C 127
12 S 555 4 166 268
47 S 556 7 183 954
24 C 230
40 C 318
29 B 559 5 159 489
17 S 560 0 140 629
38 C 117
12 B 562 8 149 553
34 C 232
17 C 171
36 S 565 4 154 443
32 S 566 2 162 876
3 S 567 9 157 70
36 S 568 8 180 300
34 C 154
5 S 570 9 156 167
8 C 161
40 S 572 1 152 889
58 S 573 6 113 996
57 B 574 4 113 461
51 B 575 6 110 794
0 B 576 6 138 651
37 C 515
58 S 578 0 142 846
14 B 579 9 197 587
24 S 580 8 132 762
62 C 130
24 B 582 4 200 129
6 C 240
34 B 584 3 110 522
9 S 585 9 116 593
24 S 586 6 200 287
10 C 480
56 B 588 2 153 451
9 C 462
48 B 590 2 121 56
56 C 235
57 C 543
43 B 593 7 126 809
7 B 594 2 125 188
21 B 595 1 184 702
5 C 203
34 S 597 8 150 693
45 S 598 9 190 581
56 B 599 1 184 323
36 S 600 0 111 785
4 B 601 8 124 162
0 S 602 0 190 471
27 B 603 4 122 812
50 C 434
48 B 605 7 165 251
11 S 606 5 163 348
36 C 305
24 C 230
46 C 497
41 C 507
6 B 611 1 174 114
23 S 612 9 154 924
52 S 613 8 151 307
12 C 562
30 C 284
60 B 616 4 179 112
39 B 617 0 167 565
46 B 618 6 134 918
30 S 619 9 156 471
22 C 379
26 B 621 2 164 561
52 C 482
25 C 199
33 C 133
16 B 625 5 142 156
45 B 626 6 173 257
5 C 506
10 B 628 6 114 127
17 C 560
11 C 391
35 S 631 4 175 258
8 C 161
11 S 633 2 160 710
